<?xml version="1.0"?>
<robot xmlns:xacro="http://www.ros.org/wiki/xacro">
  <xacro:macro name="gripper" params="offset_x offset_y offset_z parent_link">
    <!--First Joint-->
    <joint name="Cube_link_joint" type="continuous">
      <limit lower="0" upper="0" effort="5000.0000" velocity="100.00000"/>
      <origin rpy="0.00000 0.00000 0.00000" xyz="${offset_x} ${offset_y} ${offset_z}"/>
      <parent link="${parent_link}"/>
      <child link="Cube_link"/>
      <axis xyz="0.00000 0.00000 1.00000"/>
    </joint>

    <!--First Link-->
    <link name="Cube_link">
      <collision name="Cube_collision">
        <origin rpy="0.00000 0.00000 0.00000" xyz="-0.00099 -0.00000 -0.00000"/>
        <geometry>
          <box size="0.50000 0.70000 0.10000"/>
        </geometry>
      </collision>
      <inertial>
        <inertia ixx="0.04167" ixy="0.00000" ixz="0.00000" iyy="0.02167" iyz="0.00000" izz="0.06167"/>
        <origin rpy="0.00000 0.00000 0.00000" xyz="-0.00099 -0.00000 -0.00000"/>
        <mass value="1.00000"/>
      </inertial>
      <visual name="Cube">
        <origin rpy="0.00000 0.00000 0.00000" xyz="-0.00099 0.00000 -0.00000"/>
        <material name="Gripper"/>
        <geometry>
          <box size="0.50000 0.70000 0.10000"/>
        </geometry>
      </visual>
    </link>

    <!--Rest of the Joints-->
    <joint name="Cube.003_link_joint" type="prismatic">
      <limit lower="-0.35000" upper="0.00000" effort="5000.0000" velocity="100.00000"/>
      <origin rpy="1.57080 0.00000 0.00000" xyz="-0.00000 -0.34500 -0.20148"/>
      <parent link="Cube_link"/>
      <child link="Cube.003_link"/>
      <axis xyz="0.00000 0.00000 1.00000"/>
    </joint>

    <joint name="Cube.004_link_joint" type="prismatic">
      <limit lower="0.00000" upper="0.35000" effort="5000.0000" velocity="100.00000"/>
      <origin rpy="1.57080 0.00000 0.00000" xyz="-0.00000 0.34482 -0.20313"/>
      <parent link="Cube_link"/>
      <child link="Cube.004_link"/>
      <axis xyz="0.00000 0.00000 1.00000"/>
    </joint>

    <!--Rest of the Link-->
    <link name="Cube.003_link">
      <collision name="Cube.003_collision">
        <origin rpy="-1.57080 -0.00000 0.00000" xyz="-0.00099 -0.00000 -0.00000"/>
        <geometry>
          <box size="0.50000 0.01000 0.50000"/>
        </geometry>
        <surface>
          <friction>
            <ode>
              <mu>2.000000</mu>
              <mu2>2.000000</mu2>
              <slip1>0.000000</slip1>
              <slip2>0.000000</slip2>
            </ode>
          </friction>
        </surface>
      </collision>
      <inertial>
        <inertia ixx="0.02084" ixy="0.00000" ixz="0.00000" iyy="0.04167" iyz="-0.00000" izz="0.02084"/>
        <origin rpy="0.00000 0.00000 0.00000" xyz="-0.00099 0.00000 0.00000"/>
        <mass value="1.00000"/>
      </inertial>
      <visual name="Cube.003">
        <origin rpy="-1.57080 -0.00000 0.00000" xyz="-0.00099 -0.00000 0.00000"/>
        <material name="Gripper"/>
        <geometry>
          <box size="0.50000 0.01000 0.50000"/>
        </geometry>
      </visual>
    </link>

    <link name="Cube.004_link">
      <collision name="Cube.004_collision">
        <origin rpy="-1.57080 -0.00000 0.00000" xyz="-0.00099 0.00000 0.00000"/>
        <geometry>
          <box size="0.50000 0.01000 0.50000"/>
        </geometry>
        <surface>
          <friction>
            <ode>
              <mu>2.000000</mu>
              <mu2>2.000000</mu2>
              <slip1>0.000000</slip1>
              <slip2>0.000000</slip2>
            </ode>
          </friction>
        </surface>
      </collision>
      <inertial>
        <inertia ixx="0.02084" ixy="0.00000" ixz="0.00000" iyy="0.04167" iyz="-0.00000" izz="0.02084"/>
        <origin rpy="0.00000 0.00000 0.00000" xyz="-0.00099 0.00000 0.00000"/>
        <mass value="1.00000"/>
      </inertial>
      <visual name="Cube.004">
        <origin rpy="-1.57080 -0.00000 0.00000" xyz="-0.00099 0.00000 0.00000"/>
        <material name="Gripper"/>
        <geometry>
          <box size="0.50000 0.01000 0.50000"/>
        </geometry>
      </visual>
    </link>


  </xacro:macro>
</robot>