<?xml version="1.0"?>
<robot xmlns:xacro="http://www.ros.org/wiki/xacro">
  <xacro:macro name="rover_wheels" params="offset_x offset_y offset_z parent_link RotationDirection identifier">
    <!--Joint-->
    <joint name="${identifier}_Wheel_joint" type="continuous">
      <limit lower="0" upper="0" effort="5000.0000" velocity="100.00000"/>
      <origin rpy="1.57080 0.00000 0.00000" xyz="${offset_x} ${offset_y} ${offset_z}"/>
      <parent link="${parent_link}"/>
      <child link="${identifier}_Wheel_link"/>
      <axis xyz="0.00000 0.00000 ${RotationDirection}"/>
    </joint>

    <!--Link-->
    <link name="${identifier}_Wheel_link">
      <collision name="Wheel_collision">
        <origin rpy="0.00000 0.00000 0.00000" xyz="-0.00000 -0.00000 -0.00000"/>
        <geometry>
          <cylinder radius="0.30000" length="0.10000"/>
        </geometry>
        <surface>
          <friction>
            <ode>
              <mu>1.000000</mu>
              <mu2>1.000000</mu2>
              <fdir>0.000000 0.000000 1.000000</fdir>
              <slip1>0.500000</slip1>
              <slip2>0.500000</slip2>
            </ode>
          </friction>
        </surface>
      </collision>
      <inertial>
        <inertia ixx="0.02333" ixy="0.00000" ixz="0.00000" iyy="0.04500" iyz="0.00000" izz="0.02333"/>
        <origin rpy="0.00000 0.00000 0.00000" xyz="-0.00000 0.00000 -0.00000"/>
        <mass value="1.00000"/>
      </inertial>
      <visual name="${identifier}_Wheel">
        <origin rpy="0.00000 0.00000 0.00000" xyz="0.00000 0.00000 -0.00000"/>
        <material name="Wheels"/>
        <geometry>
          <cylinder radius="0.30000" length="0.10000"/>
        </geometry>
      </visual>
    </link>

  </xacro:macro>
</robot>